<?xml version="0.0" ?>
<robot name="">
	<link name="base">
		<inertial>
			<origin rpy="0.00000 -0.00000 0.00000" xyz="-0.10000 0.00000 0.07000"/>
			<mass value="0.00000"/>
			<inertia ixx="0.00000" ixy="0" ixz="0" iyy="0.00000" iyz="0" izz="0.00000"/>
		</inertial>
	</link>
	<link name="controller_box">
		<inertial>
			<origin rpy="0.00000 -0.00000 0.00000" xyz="0.00000 0.00000 0.00000"/>
			<mass value="1.00000"/>
			<inertia ixx="0.03705" ixy="0" ixz="0" iyy="0.02769" iyz="0" izz="0.01757"/>
		</inertial>
		<visual>
			<origin rpy="0.00000 -0.00000 0.00000" xyz="-0.32500 0.00000 -0.38000"/>
			<geometry>
				<box size="0.22000 0.40000 0.53000"/>
			</geometry>
			<material name="mat_0_0">
				<color rgba="1.00000 1.00000 1.00000 1.00000" />
			</material>
		</visual>
		<collision>
			<origin rpy="0.00000 -0.00000 0.00000" xyz="-0.32500 0.00000 -0.38000"/>
			<geometry>
				<box size="0.22000 0.40000 0.53000"/>
			</geometry>
		</collision>
	</link>
	<link name="pedestal_feet">
		<inertial>
			<origin rpy="0.00000 -0.00000 0.00000" xyz="0.00000 0.00000 0.00000"/>
			<mass value="1.00000"/>
			<inertia ixx="0.04918" ixy="0" ixz="0" iyy="0.05778" iyz="0" izz="0.09073"/>
		</inertial>
		<visual>
			<origin rpy="0.00000 -0.00000 0.00000" xyz="-0.12250 0.00000 -0.75800"/>
			<geometry>
				<box size="0.77000 0.70000 0.31000"/>
			</geometry>
			<material name="mat_1_0">
				<color rgba="1.00000 1.00000 1.00000 1.00000" />
			</material>
		</visual>
		<collision>
			<origin rpy="0.00000 -0.00000 0.00000" xyz="-0.12250 0.00000 -0.75800"/>
			<geometry>
				<box size="0.77000 0.70000 0.31000"/>
			</geometry>
		</collision>
	</link>
	<link name="pedestal">
		<inertial>
			<origin rpy="0.00000 -0.00000 0.00000" xyz="0.00000 0.00000 -0.50000"/>
			<mass value="1160.86398"/>
			<inertia ixx="50.10366" ixy="0" ixz="0" iyy="50.10366" iyz="0" izz="25.35404"/>
		</inertial>
		<visual>
			<origin rpy="1.57080 -0.00000 -1.57080" xyz="0.26000 0.34500 -0.91488"/>
			<geometry>
				<mesh filename="/home/scott/ScheragaThesis/cairo_simulator/src/cairo_simulator/core/../../../assets/sawyer_description/meshes/sawyer_pv/pedestal.DAE" scale="1.00000 1.00000 1.00000"/>
			</geometry>
			<material name="mat_2_0">
				<color rgba="0.20000 0.20000 0.20000 1.00000" />
			</material>
		</visual>
		<collision>
			<origin rpy="0.00000 -0.00000 0.00000" xyz="-0.02000 0.00000 -0.29000"/>
			<geometry>
				<cylinder length="0.62000" radius="0.18000"/>
			</geometry>
		</collision>
	</link>
	<link name="right_arm_base_link">
		<inertial>
			<origin rpy="0.00000 -0.00000 0.00000" xyz="-0.00062 -0.00003 0.06540"/>
			<mass value="2.06870"/>
			<inertia ixx="0.01462" ixy="0" ixz="0" iyy="0.01462" iyz="0" izz="0.00905"/>
		</inertial>
		<visual>
			<origin rpy="0.00000 -0.00000 0.00000" xyz="0.00000 0.00000 0.00000"/>
			<geometry>
				<mesh filename="/home/scott/ScheragaThesis/cairo_simulator/src/cairo_simulator/core/../../../assets/sawyer_description/meshes/sawyer_pv/base.DAE" scale="1.00000 1.00000 1.00000"/>
			</geometry>
			<material name="mat_3_0">
				<color rgba="0.50000 0.10000 0.10000 1.00000" />
			</material>
		</visual>
		<collision>
			<origin rpy="0.00000 -0.00000 0.00000" xyz="0.00000 0.00000 0.12000"/>
			<geometry>
				<cylinder length="0.24000" radius="0.08000"/>
			</geometry>
		</collision>
	</link>
	<link name="right_l0">
		<inertial>
			<origin rpy="0.00000 -0.00000 0.00000" xyz="0.02437 0.01097 0.14363"/>
			<mass value="5.32130"/>
			<inertia ixx="0.01788" ixy="0" ixz="0" iyy="0.01788" iyz="0" izz="0.01788"/>
		</inertial>
		<visual>
			<origin rpy="0.00000 -0.00000 0.00000" xyz="0.00000 0.00000 0.00000"/>
			<geometry>
				<mesh filename="/home/scott/ScheragaThesis/cairo_simulator/src/cairo_simulator/core/../../../assets/sawyer_description/meshes/sawyer_mp3/l0.DAE" scale="1.00000 1.00000 1.00000"/>
			</geometry>
			<material name="mat_4_0">
				<color rgba="0.50000 0.10000 0.10000 1.00000" />
			</material>
		</visual>
		<collision>
			<origin rpy="0.00000 -0.00000 0.00000" xyz="0.08000 0.00000 0.23000"/>
			<geometry>
				<sphere radius="0.07000"/>
			</geometry>
		</collision>
	</link>
	<link name="head">
		<inertial>
			<origin rpy="0.00000 -0.00000 0.00000" xyz="0.00532 -0.00003 0.10210"/>
			<mass value="1.57950"/>
			<inertia ixx="0.03450" ixy="0" ixz="0" iyy="0.03450" iyz="0" izz="0.03450"/>
		</inertial>
		<visual>
			<origin rpy="0.00000 -0.00000 0.00000" xyz="0.00000 0.00000 0.00000"/>
			<geometry>
				<mesh filename="/home/scott/ScheragaThesis/cairo_simulator/src/cairo_simulator/core/../../../assets/sawyer_description/meshes/sawyer_pv/head.DAE" scale="1.00000 1.00000 1.00000"/>
			</geometry>
			<material name="mat_5_0">
				<color rgba="0.50000 0.10000 0.10000 1.00000" />
			</material>
		</visual>
		<collision>
			<origin rpy="0.00000 -0.00000 0.00000" xyz="0.00000 0.00000 0.08000"/>
			<geometry>
				<sphere radius="0.18000"/>
			</geometry>
		</collision>
	</link>
	<link name="screen">
		<inertial>
			<origin rpy="0.00000 -0.00000 0.00000" xyz="0.00000 0.00000 0.00000"/>
			<mass value="0.00010"/>
			<inertia ixx="0.00000" ixy="0" ixz="0" iyy="0.00000" iyz="0" izz="0.00000"/>
		</inertial>
		<visual>
			<origin rpy="0.00000 -0.00000 0.00000" xyz="0.00000 0.00000 0.00000"/>
			<geometry>
				<box size="0.24000 0.14000 0.00200"/>
			</geometry>
			<material name="mat_6_0">
				<color rgba="0.20000 0.20000 0.20000 1.00000" />
			</material>
		</visual>
		<collision>
			<origin rpy="0.00000 -0.00000 0.00000" xyz="0.00000 0.00000 0.00000"/>
			<geometry>
				<sphere radius="0.00100"/>
			</geometry>
		</collision>
	</link>
	<link name="head_camera">
		<inertial>
			<origin rpy="0.00000 -0.00000 0.00000" xyz="0.00000 0.00000 0.00000"/>
			<mass value="1.00000"/>
			<inertia ixx="0.00000" ixy="0" ixz="0" iyy="0.00000" iyz="0" izz="0.00000"/>
		</inertial>
	</link>
	<link name="right_torso_itb">
		<inertial>
			<origin rpy="0.00000 -0.00000 0.00000" xyz="0.00000 0.00000 0.00000"/>
			<mass value="0.00010"/>
			<inertia ixx="0.00000" ixy="0" ixz="0" iyy="0.00000" iyz="0" izz="0.00000"/>
		</inertial>
	</link>
	<link name="right_l1">
		<inertial>
			<origin rpy="0.00000 -0.00000 0.00000" xyz="-0.00308 -0.02681 0.09252"/>
			<mass value="4.50500"/>
			<inertia ixx="0.01514" ixy="0" ixz="0" iyy="0.01514" iyz="0" izz="0.01514"/>
		</inertial>
		<visual>
			<origin rpy="0.00000 -0.00000 0.00000" xyz="0.00000 0.00000 0.00000"/>
			<geometry>
				<mesh filename="/home/scott/ScheragaThesis/cairo_simulator/src/cairo_simulator/core/../../../assets/sawyer_description/meshes/sawyer_mp3/l1.DAE" scale="1.00000 1.00000 1.00000"/>
			</geometry>
			<material name="mat_9_0">
				<color rgba="0.50000 0.10000 0.10000 1.00000" />
			</material>
		</visual>
		<collision>
			<origin rpy="0.00000 -0.00000 0.00000" xyz="0.00000 0.00000 0.12250"/>
			<geometry>
				<sphere radius="0.07000"/>
			</geometry>
		</collision>
	</link>
	<link name="right_l2">
		<inertial>
			<origin rpy="0.00000 -0.00000 0.00000" xyz="-0.00016 -0.01497 0.13582"/>
			<mass value="1.74500"/>
			<inertia ixx="0.01917" ixy="0" ixz="0" iyy="0.01917" iyz="0" izz="0.00433"/>
		</inertial>
		<visual>
			<origin rpy="0.00000 -0.00000 0.00000" xyz="0.00000 0.00000 0.00000"/>
			<geometry>
				<mesh filename="/home/scott/ScheragaThesis/cairo_simulator/src/cairo_simulator/core/../../../assets/sawyer_description/meshes/sawyer_pv/l2.DAE" scale="1.00000 1.00000 1.00000"/>
			</geometry>
			<material name="mat_10_0">
				<color rgba="0.50000 0.10000 0.10000 1.00000" />
			</material>
		</visual>
		<collision>
			<origin rpy="0.00000 -0.00000 0.00000" xyz="0.00000 0.00000 0.08000"/>
			<geometry>
				<cylinder length="0.34000" radius="0.06000"/>
			</geometry>
		</collision>
	</link>
	<link name="right_l3">
		<inertial>
			<origin rpy="0.00000 -0.00000 0.00000" xyz="-0.00481 -0.02810 -0.08415"/>
			<mass value="2.50970"/>
			<inertia ixx="0.00623" ixy="0" ixz="0" iyy="0.00623" iyz="0" izz="0.00623"/>
		</inertial>
		<visual>
			<origin rpy="0.00000 -0.00000 0.00000" xyz="0.00000 0.00000 0.00000"/>
			<geometry>
				<mesh filename="/home/scott/ScheragaThesis/cairo_simulator/src/cairo_simulator/core/../../../assets/sawyer_description/meshes/sawyer_pv/l3.DAE" scale="1.00000 1.00000 1.00000"/>
			</geometry>
			<material name="mat_11_0">
				<color rgba="0.50000 0.10000 0.10000 1.00000" />
			</material>
		</visual>
		<collision>
			<origin rpy="0.00000 -0.00000 0.00000" xyz="0.00000 -0.01000 -0.12000"/>
			<geometry>
				<sphere radius="0.06000"/>
			</geometry>
		</collision>
	</link>
	<link name="right_l4">
		<inertial>
			<origin rpy="0.00000 -0.00000 0.00000" xyz="-0.00188 0.00690 0.13410"/>
			<mass value="1.11360"/>
			<inertia ixx="0.00925" ixy="0" ixz="0" iyy="0.00925" iyz="0" izz="0.00157"/>
		</inertial>
		<visual>
			<origin rpy="0.00000 -0.00000 0.00000" xyz="0.00000 0.00000 0.00000"/>
			<geometry>
				<mesh filename="/home/scott/ScheragaThesis/cairo_simulator/src/cairo_simulator/core/../../../assets/sawyer_description/meshes/sawyer_pv/l4.DAE" scale="1.00000 1.00000 1.00000"/>
			</geometry>
			<material name="mat_12_0">
				<color rgba="0.50000 0.10000 0.10000 1.00000" />
			</material>
		</visual>
		<collision>
			<origin rpy="0.00000 -0.00000 0.00000" xyz="0.00000 0.00000 0.11000"/>
			<geometry>
				<cylinder length="0.30000" radius="0.04500"/>
			</geometry>
		</collision>
	</link>
	<link name="right_arm_itb">
		<inertial>
			<origin rpy="0.00000 -0.00000 0.00000" xyz="0.00000 0.00000 0.00000"/>
			<mass value="0.00010"/>
			<inertia ixx="0.00000" ixy="0" ixz="0" iyy="0.00000" iyz="0" izz="0.00000"/>
		</inertial>
	</link>
	<link name="right_l5">
		<inertial>
			<origin rpy="0.00000 -0.00000 0.00000" xyz="0.00611 -0.02370 0.07642"/>
			<mass value="1.56250"/>
			<inertia ixx="0.00388" ixy="0" ixz="0" iyy="0.00388" iyz="0" izz="0.00388"/>
		</inertial>
		<visual>
			<origin rpy="0.00000 -0.00000 0.00000" xyz="0.00000 0.00000 0.00000"/>
			<geometry>
				<mesh filename="/home/scott/ScheragaThesis/cairo_simulator/src/cairo_simulator/core/../../../assets/sawyer_description/meshes/sawyer_pv/l5.DAE" scale="1.00000 1.00000 1.00000"/>
			</geometry>
			<material name="mat_14_0">
				<color rgba="0.50000 0.10000 0.10000 1.00000" />
			</material>
		</visual>
		<collision>
			<origin rpy="0.00000 -0.00000 0.00000" xyz="0.00000 0.00000 0.10000"/>
			<geometry>
				<sphere radius="0.06000"/>
			</geometry>
		</collision>
	</link>
	<link name="right_hand_camera">
		<inertial>
			<origin rpy="0.00000 -0.00000 0.00000" xyz="0.00000 0.00000 0.00000"/>
			<mass value="1.00000"/>
			<inertia ixx="0.00000" ixy="0" ixz="0" iyy="0.00000" iyz="0" izz="0.00000"/>
		</inertial>
	</link>
	<link name="right_wrist">
		<inertial>
			<origin rpy="0.00000 -0.00000 0.00000" xyz="0.00000 0.00000 0.00000"/>
			<mass value="1.00000"/>
			<inertia ixx="0.00000" ixy="0" ixz="0" iyy="0.00000" iyz="0" izz="0.00000"/>
		</inertial>
	</link>
	<link name="right_l6">
		<inertial>
			<origin rpy="0.00000 -0.00000 0.00000" xyz="-0.00001 0.00858 -0.00496"/>
			<mass value="0.32920"/>
			<inertia ixx="0.00042" ixy="0" ixz="0" iyy="0.00042" iyz="0" izz="0.00069"/>
		</inertial>
		<visual>
			<origin rpy="0.00000 -0.00000 0.00000" xyz="0.00000 0.00000 0.00000"/>
			<geometry>
				<mesh filename="/home/scott/ScheragaThesis/cairo_simulator/src/cairo_simulator/core/../../../assets/sawyer_description/meshes/sawyer_mp1/l6.DAE" scale="1.00000 1.00000 1.00000"/>
			</geometry>
			<material name="mat_17_0">
				<color rgba="0.50000 0.10000 0.10000 1.00000" />
			</material>
		</visual>
		<collision>
			<origin rpy="0.00000 -0.00000 0.00000" xyz="0.00000 0.01500 -0.01000"/>
			<geometry>
				<cylinder length="0.05000" radius="0.05500"/>
			</geometry>
		</collision>
	</link>
	<link name="right_hand">
		<inertial>
			<origin rpy="0.00000 -0.00000 0.00000" xyz="0.00000 0.00000 0.00000"/>
			<mass value="0.00000"/>
			<inertia ixx="0.00000" ixy="0" ixz="0" iyy="0.00000" iyz="0" izz="0.00000"/>
		</inertial>
		<visual>
			<origin rpy="0.00000 -0.00000 0.00000" xyz="0.00000 0.00000 0.02000"/>
			<geometry>
				<cylinder length="0.03000" radius="0.03500"/>
			</geometry>
			<material name="mat_18_0">
				<color rgba="1.00000 1.00000 1.00000 1.00000" />
			</material>
		</visual>
		<collision>
			<origin rpy="0.00000 -0.00000 0.00000" xyz="0.00000 0.00000 0.02000"/>
			<geometry>
				<cylinder length="0.03000" radius="0.03500"/>
			</geometry>
		</collision>
	</link>
	<link name="right_gripper_base">
		<inertial>
			<origin rpy="0.00000 -0.00000 0.00000" xyz="0.00280 -0.00040 0.03430"/>
			<mass value="0.47000"/>
			<inertia ixx="0.00000" ixy="0" ixz="0" iyy="0.00000" iyz="0" izz="0.00000"/>
		</inertial>
	</link>
	<link name="right_connector_plate_base">
		<inertial>
			<origin rpy="0.00000 -0.00000 0.00000" xyz="0.00000 0.00000 0.00000"/>
			<mass value="0.00000"/>
			<inertia ixx="0.00000" ixy="0" ixz="0" iyy="0.00000" iyz="0" izz="0.00000"/>
		</inertial>
		<visual>
			<origin rpy="0.00000 -0.00000 0.00000" xyz="0.00000 0.00000 0.00000"/>
			<geometry>
				<mesh filename="/home/scott/ScheragaThesis/cairo_simulator/src/cairo_simulator/core/../../../assets/sawyer_description/urdf/../meshes/connector_plate/connector_plate.STL" scale="1.00000 1.00000 1.00000"/>
			</geometry>
			<material name="mat_20_0">
				<color rgba="0.05000 0.05000 0.05000 1.00000" />
			</material>
		</visual>
		<collision>
			<origin rpy="0.00000 -0.00000 0.00000" xyz="0.00000 0.00000 0.01350"/>
			<geometry>
				<cylinder length="0.03020" radius="0.04000"/>
			</geometry>
		</collision>
	</link>
	<link name="right_connector_plate_mount">
		<inertial>
			<origin rpy="0.00000 -0.00000 0.00000" xyz="0.00000 0.00000 0.00000"/>
			<mass value="1.00000"/>
			<inertia ixx="0.00000" ixy="0" ixz="0" iyy="0.00000" iyz="0" izz="0.00000"/>
		</inertial>
	</link>
	<link name="right_electric_gripper_base">
		<inertial>
			<origin rpy="1.57080 -0.00000 3.14159" xyz="0.00000 0.00000 0.00000"/>
			<mass value="0.00000"/>
			<inertia ixx="0.00000" ixy="0" ixz="0" iyy="0.00000" iyz="0" izz="0.00000"/>
		</inertial>
		<visual>
			<origin rpy="0.00000 -0.00000 0.00000" xyz="0.00000 0.00000 0.00000"/>
			<geometry>
				<mesh filename="/home/scott/ScheragaThesis/cairo_simulator/src/cairo_simulator/core/../../../assets/sawyer_description/meshes/electric_gripper/electric_gripper_base.DAE" scale="1.00000 1.00000 1.00000"/>
			</geometry>
			<material name="mat_22_0">
				<color rgba="1.00000 1.00000 1.00000 1.00000" />
			</material>
		</visual>
		<collision>
			<origin rpy="1.57080 -0.00000 3.14159" xyz="0.00400 -0.00000 0.02500"/>
			<geometry>
				<cylinder length="0.10000" radius="0.02900"/>
			</geometry>
		</collision>
	</link>
	<link name="right_gripper_l_finger">
		<inertial>
			<origin rpy="0.00000 -0.00000 3.14159" xyz="0.00000 0.00000 0.00000"/>
			<mass value="0.00100"/>
			<inertia ixx="0.00000" ixy="0" ixz="0" iyy="0.00000" iyz="0" izz="0.00000"/>
		</inertial>
		<visual>
			<origin rpy="0.00000 -0.00000 3.14159" xyz="0.00000 0.00000 0.00000"/>
			<geometry>
				<mesh filename="/home/scott/ScheragaThesis/cairo_simulator/src/cairo_simulator/core/../../../assets/sawyer_description/meshes/electric_gripper/fingers/standard_narrow.DAE" scale="1.00000 1.00000 1.00000"/>
			</geometry>
			<material name="mat_23_0">
				<color rgba="1.00000 1.00000 1.00000 1.00000" />
			</material>
		</visual>
		<collision>
			<origin rpy="0.00000 -0.00000 3.14159" xyz="0.00000 0.01725 0.04000"/>
			<geometry>
				<box size="0.01000 0.01350 0.07500"/>
			</geometry>
		</collision>
		<collision>
			<origin rpy="0.00000 -0.00000 3.14159" xyz="-0.00500 -0.00300 0.00830"/>
			<geometry>
				<box size="0.01000 0.05000 0.01700"/>
			</geometry>
		</collision>
	</link>
	<link name="right_gripper_l_finger_tip">
		<inertial>
			<origin rpy="0.00000 -0.00000 -3.14159" xyz="0.00000 0.00000 0.00000"/>
			<mass value="0.00100"/>
			<inertia ixx="0.00000" ixy="0" ixz="0" iyy="0.00000" iyz="0" izz="0.00000"/>
		</inertial>
		<visual>
			<origin rpy="0.00000 -0.00000 -3.14159" xyz="0.00000 0.00000 0.00000"/>
			<geometry>
				<mesh filename="/home/scott/ScheragaThesis/cairo_simulator/src/cairo_simulator/core/../../../assets/sawyer_description/meshes/electric_gripper/fingers/basic_soft_tip.DAE" scale="1.00000 1.00000 1.00000"/>
			</geometry>
			<material name="mat_24_0">
				<color rgba="1.00000 1.00000 1.00000 1.00000" />
			</material>
		</visual>
		<collision>
			<origin rpy="0.00000 -0.00000 -3.14159" xyz="-0.00000 -0.00450 -0.01500"/>
			<geometry>
				<box size="0.01600 0.00700 0.03700"/>
			</geometry>
		</collision>
	</link>
	<link name="right_gripper_r_finger">
		<inertial>
			<origin rpy="0.00000 -0.00000 0.00000" xyz="0.00000 0.00000 0.00000"/>
			<mass value="0.00100"/>
			<inertia ixx="0.00000" ixy="0" ixz="0" iyy="0.00000" iyz="0" izz="0.00000"/>
		</inertial>
		<visual>
			<origin rpy="0.00000 -0.00000 0.00000" xyz="0.00000 0.00000 0.00000"/>
			<geometry>
				<mesh filename="/home/scott/ScheragaThesis/cairo_simulator/src/cairo_simulator/core/../../../assets/sawyer_description/meshes/electric_gripper/fingers/standard_narrow.DAE" scale="1.00000 1.00000 1.00000"/>
			</geometry>
			<material name="mat_25_0">
				<color rgba="1.00000 1.00000 1.00000 1.00000" />
			</material>
		</visual>
		<collision>
			<origin rpy="0.00000 -0.00000 0.00000" xyz="0.00000 -0.01725 0.04000"/>
			<geometry>
				<box size="0.01000 0.01350 0.07500"/>
			</geometry>
		</collision>
		<collision>
			<origin rpy="0.00000 -0.00000 0.00000" xyz="0.00500 0.00300 0.00830"/>
			<geometry>
				<box size="0.01000 0.05000 0.01700"/>
			</geometry>
		</collision>
	</link>
	<link name="right_gripper_r_finger_tip">
		<inertial>
			<origin rpy="0.00000 -0.00000 0.00000" xyz="0.00000 0.00000 0.00000"/>
			<mass value="0.00100"/>
			<inertia ixx="0.00000" ixy="0" ixz="0" iyy="0.00000" iyz="0" izz="0.00000"/>
		</inertial>
		<visual>
			<origin rpy="0.00000 -0.00000 0.00000" xyz="0.00000 0.00000 0.00000"/>
			<geometry>
				<mesh filename="/home/scott/ScheragaThesis/cairo_simulator/src/cairo_simulator/core/../../../assets/sawyer_description/meshes/electric_gripper/fingers/basic_soft_tip.DAE" scale="1.00000 1.00000 1.00000"/>
			</geometry>
			<material name="mat_26_0">
				<color rgba="1.00000 1.00000 1.00000 1.00000" />
			</material>
		</visual>
		<collision>
			<origin rpy="0.00000 -0.00000 0.00000" xyz="0.00000 0.00450 -0.01500"/>
			<geometry>
				<box size="0.01600 0.00700 0.03700"/>
			</geometry>
		</collision>
	</link>
	<link name="right_gripper_tip">
		<inertial>
			<origin rpy="0.00000 -0.00000 0.00000" xyz="0.00000 0.00000 0.00000"/>
			<mass value="0.00000"/>
			<inertia ixx="0.00000" ixy="0" ixz="0" iyy="0.00000" iyz="0" izz="0.00000"/>
		</inertial>
	</link>
	<link name="right_l4_2">
		<inertial>
			<origin rpy="0.00000 -0.00000 0.00000" xyz="0.00000 0.00000 0.00000"/>
			<mass value="0.00000"/>
			<inertia ixx="0.00000" ixy="0" ixz="0" iyy="0.00000" iyz="0" izz="0.00000"/>
		</inertial>
		<visual>
			<origin rpy="0.00000 -0.00000 0.00000" xyz="0.00000 0.01000 0.26000"/>
			<geometry>
				<sphere radius="0.06000"/>
			</geometry>
			<material name="mat_28_0">
				<color rgba="1.00000 1.00000 1.00000 1.00000" />
			</material>
		</visual>
		<collision>
			<origin rpy="0.00000 -0.00000 0.00000" xyz="0.00000 0.01000 0.26000"/>
			<geometry>
				<sphere radius="0.06000"/>
			</geometry>
		</collision>
	</link>
	<link name="right_l2_2">
		<inertial>
			<origin rpy="0.00000 -0.00000 0.00000" xyz="0.00000 0.00000 0.00000"/>
			<mass value="0.00000"/>
			<inertia ixx="0.00000" ixy="0" ixz="0" iyy="0.00000" iyz="0" izz="0.00000"/>
		</inertial>
		<visual>
			<origin rpy="0.00000 -0.00000 0.00000" xyz="0.00000 0.00000 0.26000"/>
			<geometry>
				<sphere radius="0.06000"/>
			</geometry>
			<material name="mat_29_0">
				<color rgba="1.00000 1.00000 1.00000 1.00000" />
			</material>
		</visual>
		<collision>
			<origin rpy="0.00000 -0.00000 0.00000" xyz="0.00000 0.00000 0.26000"/>
			<geometry>
				<sphere radius="0.06000"/>
			</geometry>
		</collision>
	</link>
	<link name="right_l1_2">
		<inertial>
			<origin rpy="0.00000 -0.00000 0.00000" xyz="0.00000 0.00000 0.00000"/>
			<mass value="0.00000"/>
			<inertia ixx="0.00000" ixy="0" ixz="0" iyy="0.00000" iyz="0" izz="0.00000"/>
		</inertial>
		<visual>
			<origin rpy="0.00000 -0.00000 0.00000" xyz="0.00000 0.00000 0.03500"/>
			<geometry>
				<cylinder length="0.14000" radius="0.07000"/>
			</geometry>
			<material name="mat_30_0">
				<color rgba="1.00000 1.00000 1.00000 1.00000" />
			</material>
		</visual>
		<collision>
			<origin rpy="0.00000 -0.00000 0.00000" xyz="0.00000 0.00000 0.03500"/>
			<geometry>
				<cylinder length="0.14000" radius="0.07000"/>
			</geometry>
		</collision>
	</link>
	<link name="torso">
		<inertial>
			<origin rpy="0.00000 -0.00000 0.00000" xyz="0.00000 0.00000 0.00000"/>
			<mass value="0.00010"/>
			<inertia ixx="0.00000" ixy="0" ixz="0" iyy="0.00000" iyz="0" izz="0.00000"/>
		</inertial>
		<visual>
			<origin rpy="0.00000 -0.00000 0.00000" xyz="0.00000 0.00000 0.00000"/>
			<geometry>
				<box size="0.00100 0.00100 0.00100"/>
			</geometry>
			<material name="mat_31_0">
				<color rgba="0.20000 0.20000 0.20000 1.00000" />
			</material>
		</visual>
	</link>
	<link name="1in rectangular block_C.SLDPRT">
		<inertial>
			<origin rpy="0.00000 -0.00000 0.00000" xyz="0.00000 0.15000 0.03810"/>
			<mass value="0.04916"/>
			<inertia ixx="0.00003" ixy="0" ixz="0" iyy="0.00003" iyz="0" izz="0.00001"/>
		</inertial>
		<visual>
			<origin rpy="1.57080 -0.00000 0.00000" xyz="0.00000 0.00000 0.15000"/>
			<geometry>
				<mesh filename="./1in rectangular block_C.SLDPRT/meshes/1in rectangular block_C.SLDPRT.STL" scale="1.00000 1.00000 1.00000"/>
			</geometry>
			<material name="mat_-1_0">
				<color rgba="1.00000 0.00000 0.00000 1.00000" />
			</material>
		</visual>
		<collision>
			<origin rpy="1.57080 -0.00000 0.00000" xyz="0.00000 0.00000 0.15000"/>
			<geometry>
				<mesh filename="./1in rectangular block_C.SLDPRT/meshes/1in rectangular block_C.SLDPRT.STL" scale="1.00000 1.00000 1.00000"/>
			</geometry>
		</collision>
	</link>
	<joint name="controller_box_fixed" type="fixed">
		<parent link="base"/>
		<child link="controller_box"/>
		<dynamics damping="1.0" friction="0.0001"/>
		<origin rpy="0.00000 -0.00000 0.00000" xyz="0.00000 0.00000 0.00000"/>
		<axis xyz="0.00000 0.00000 0.00000"/>
	</joint>
	<joint name="pedestal_feet_fixed" type="fixed">
		<parent link="base"/>
		<child link="pedestal_feet"/>
		<dynamics damping="1.0" friction="0.0001"/>
		<origin rpy="0.00000 -0.00000 0.00000" xyz="0.00000 0.00000 0.00000"/>
		<axis xyz="0.00000 0.00000 0.00000"/>
	</joint>
	<joint name="pedestal_fixed" type="fixed">
		<parent link="base"/>
		<child link="pedestal"/>
		<dynamics damping="1.0" friction="0.0001"/>
		<origin rpy="0.00000 -0.00000 0.00000" xyz="0.00000 0.00000 0.00000"/>
		<axis xyz="0.00000 0.00000 0.00000"/>
	</joint>
	<joint name="right_arm_mount" type="fixed">
		<parent link="base"/>
		<child link="right_arm_base_link"/>
		<dynamics damping="1.0" friction="0.0001"/>
		<origin rpy="0.00000 -0.00000 0.00000" xyz="0.00000 0.00000 0.00000"/>
		<axis xyz="0.00000 0.00000 0.00000"/>
	</joint>
	<joint name="right_j0" type="revolute">
		<parent link="right_arm_base_link"/>
		<child link="right_l0"/>
		<dynamics damping="1.0" friction="0.0001"/>
		<origin rpy="0.00000 -0.00000 0.00000" xyz="0.00000 0.00000 0.08000"/>
		<axis xyz="0.00000 0.00000 1.00000"/>
	</joint>
	<joint name="head_pan" type="revolute">
		<parent link="right_l0"/>
		<child link="head"/>
		<dynamics damping="1.0" friction="0.0001"/>
		<origin rpy="0.00000 -0.00000 0.00000" xyz="0.00000 0.00000 0.29650"/>
		<axis xyz="0.00000 0.00000 1.00000"/>
	</joint>
	<joint name="display_joint" type="fixed">
		<parent link="head"/>
		<child link="screen"/>
		<dynamics damping="1.0" friction="0.0001"/>
		<origin rpy="1.57080 -0.00000 1.57080" xyz="0.03000 0.00000 0.10500"/>
		<axis xyz="0.00000 0.00000 0.00000"/>
	</joint>
	<joint name="head_camera" type="fixed">
		<parent link="head"/>
		<child link="head_camera"/>
		<dynamics damping="1.0" friction="0.0001"/>
		<origin rpy="-2.12930 -0.00000 -1.57080" xyz="0.02280 0.00000 0.21657"/>
		<axis xyz="0.00000 0.00000 0.00000"/>
	</joint>
	<joint name="right_torso_itb" type="fixed">
		<parent link="right_l0"/>
		<child link="right_torso_itb"/>
		<dynamics damping="1.0" friction="0.0001"/>
		<origin rpy="0.00000 -1.57080 0.00000" xyz="-0.05500 0.00000 0.22000"/>
		<axis xyz="0.00000 0.00000 0.00000"/>
	</joint>
	<joint name="right_j1" type="revolute">
		<parent link="right_l0"/>
		<child link="right_l1"/>
		<dynamics damping="1.0" friction="0.0001"/>
		<origin rpy="0.00000 1.57080 -4.71239" xyz="0.08100 0.05000 0.23700"/>
		<axis xyz="0.00000 0.00000 1.00000"/>
	</joint>
	<joint name="right_j2" type="revolute">
		<parent link="right_l1"/>
		<child link="right_l2"/>
		<dynamics damping="1.0" friction="0.0001"/>
		<origin rpy="1.57080 -0.00000 0.00000" xyz="0.00000 -0.14000 0.14250"/>
		<axis xyz="0.00000 0.00000 1.00000"/>
	</joint>
	<joint name="right_j3" type="revolute">
		<parent link="right_l2"/>
		<child link="right_l3"/>
		<dynamics damping="1.0" friction="0.0001"/>
		<origin rpy="-1.57080 0.00000 0.00000" xyz="0.00000 -0.04200 0.26000"/>
		<axis xyz="0.00000 0.00000 1.00000"/>
	</joint>
	<joint name="right_j4" type="revolute">
		<parent link="right_l3"/>
		<child link="right_l4"/>
		<dynamics damping="1.0" friction="0.0001"/>
		<origin rpy="1.57080 -0.00000 0.00000" xyz="0.00000 -0.12500 -0.12650"/>
		<axis xyz="0.00000 0.00000 1.00000"/>
	</joint>
	<joint name="right_arm_itb" type="fixed">
		<parent link="right_l4"/>
		<child link="right_arm_itb"/>
		<dynamics damping="1.0" friction="0.0001"/>
		<origin rpy="0.00000 -1.57080 0.00000" xyz="-0.05500 0.00000 0.07500"/>
		<axis xyz="0.00000 0.00000 0.00000"/>
	</joint>
	<joint name="right_j5" type="revolute">
		<parent link="right_l4"/>
		<child link="right_l5"/>
		<dynamics damping="1.0" friction="0.0001"/>
		<origin rpy="-1.57080 0.00000 0.00000" xyz="0.00000 0.03100 0.27500"/>
		<axis xyz="0.00000 0.00000 1.00000"/>
	</joint>
	<joint name="right_hand_camera" type="fixed">
		<parent link="right_l5"/>
		<child link="right_hand_camera"/>
		<dynamics damping="1.0" friction="0.0001"/>
		<origin rpy="0.00000 1.57080 -0.00000" xyz="0.03955 -0.03300 0.06950"/>
		<axis xyz="0.00000 0.00000 0.00000"/>
	</joint>
	<joint name="right_wrist" type="fixed">
		<parent link="right_l5"/>
		<child link="right_wrist"/>
		<dynamics damping="1.0" friction="0.0001"/>
		<origin rpy="1.57080 -0.00000 0.00000" xyz="0.00000 0.00000 0.10541"/>
		<axis xyz="0.00000 0.00000 0.00000"/>
	</joint>
	<joint name="right_j6" type="revolute">
		<parent link="right_l5"/>
		<child link="right_l6"/>
		<dynamics damping="1.0" friction="0.0001"/>
		<origin rpy="-1.57080 -0.17453 -3.14159" xyz="0.00000 -0.11000 0.10530"/>
		<axis xyz="0.00000 0.00000 1.00000"/>
	</joint>
	<joint name="right_hand" type="fixed">
		<parent link="right_l6"/>
		<child link="right_hand"/>
		<dynamics damping="1.0" friction="0.0001"/>
		<origin rpy="0.00000 -0.00000 1.57080" xyz="0.00000 0.00000 0.02450"/>
		<axis xyz="0.00000 0.00000 0.00000"/>
	</joint>
	<joint name="right_gripper_base_joint" type="fixed">
		<parent link="right_hand"/>
		<child link="right_gripper_base"/>
		<dynamics damping="1.0" friction="0.0001"/>
		<origin rpy="0.00000 -0.00000 0.00000" xyz="0.00000 0.00000 -0.00500"/>
		<axis xyz="0.00000 0.00000 0.00000"/>
	</joint>
	<joint name="right_connector_plate_base_joint" type="fixed">
		<parent link="right_gripper_base"/>
		<child link="right_connector_plate_base"/>
		<dynamics damping="1.0" friction="0.0001"/>
		<origin rpy="0.00000 -0.00000 0.00000" xyz="0.00000 0.00000 0.00180"/>
		<axis xyz="0.00000 0.00000 0.00000"/>
	</joint>
	<joint name="right_connector_plate_mount_joint" type="fixed">
		<parent link="right_connector_plate_base"/>
		<child link="right_connector_plate_mount"/>
		<dynamics damping="1.0" friction="0.0001"/>
		<origin rpy="0.00000 -0.00000 0.00000" xyz="0.00000 0.00000 0.01760"/>
		<axis xyz="0.00000 0.00000 0.00000"/>
	</joint>
	<joint name="right_electric_gripper_base_joint" type="fixed">
		<parent link="right_connector_plate_mount"/>
		<child link="right_electric_gripper_base"/>
		<dynamics damping="1.0" friction="0.0001"/>
		<origin rpy="0.00000 -0.00000 0.00000" xyz="0.00000 0.00000 0.00000"/>
		<axis xyz="0.00000 0.00000 0.00000"/>
	</joint>
	<joint name="right_gripper_l_finger_joint" type="prismatic">
		<parent link="right_electric_gripper_base"/>
		<child link="right_gripper_l_finger"/>
<limit effort="1000.0" lower="-0.50000" upper="0.50000" velocity="0.5"/>		<dynamics damping="1.0" friction="0.0001"/>
		<origin rpy="-0.00000 -0.00000 -0.00000" xyz="0.00300 -0.00150 0.04552"/>
		<axis xyz="0.00000 -1.00000 0.00000"/>
	</joint>
	<joint name="right_gripper_l_finger_tip_joint" type="fixed">
		<parent link="right_gripper_l_finger"/>
		<child link="right_gripper_l_finger_tip"/>
		<dynamics damping="1.0" friction="0.0001"/>
		<origin rpy="0.00000 -0.00000 0.00000" xyz="0.00000 0.01725 0.07500"/>
		<axis xyz="0.00000 0.00000 0.00000"/>
	</joint>
	<joint name="right_gripper_r_finger_joint" type="prismatic">
		<parent link="right_electric_gripper_base"/>
		<child link="right_gripper_r_finger"/>
<limit effort="1000.0" lower="-0.50000" upper="0.50000" velocity="0.5"/>		<dynamics damping="1.0" friction="0.0001"/>
		<origin rpy="0.00000 -0.00000 0.00000" xyz="0.00300 0.00150 0.04552"/>
		<axis xyz="0.00000 1.00000 0.00000"/>
	</joint>
	<joint name="right_gripper_r_finger_tip_joint" type="fixed">
		<parent link="right_gripper_r_finger"/>
		<child link="right_gripper_r_finger_tip"/>
		<dynamics damping="1.0" friction="0.0001"/>
		<origin rpy="0.00000 -0.00000 0.00000" xyz="0.00000 -0.01725 0.07500"/>
		<axis xyz="0.00000 0.00000 0.00000"/>
	</joint>
	<joint name="right_gripper_tip_joint" type="fixed">
		<parent link="right_gripper_base"/>
		<child link="right_gripper_tip"/>
		<dynamics damping="1.0" friction="0.0001"/>
		<origin rpy="0.00000 -0.00000 0.00000" xyz="0.00000 0.00000 0.14062"/>
		<axis xyz="0.00000 0.00000 0.00000"/>
	</joint>
	<joint name="right_j4_2" type="fixed">
		<parent link="right_l4"/>
		<child link="right_l4_2"/>
		<dynamics damping="1.0" friction="0.0001"/>
		<origin rpy="0.00000 -0.00000 0.00000" xyz="0.00000 0.00000 0.00000"/>
		<axis xyz="0.00000 0.00000 0.00000"/>
	</joint>
	<joint name="right_j2_2" type="fixed">
		<parent link="right_l2"/>
		<child link="right_l2_2"/>
		<dynamics damping="1.0" friction="0.0001"/>
		<origin rpy="0.00000 -0.00000 0.00000" xyz="0.00000 0.00000 0.00000"/>
		<axis xyz="0.00000 0.00000 0.00000"/>
	</joint>
	<joint name="right_j1_2" type="fixed">
		<parent link="right_l1"/>
		<child link="right_l1_2"/>
		<dynamics damping="1.0" friction="0.0001"/>
		<origin rpy="0.00000 -0.00000 0.00000" xyz="0.00000 0.00000 0.00000"/>
		<axis xyz="0.00000 0.00000 0.00000"/>
	</joint>
	<joint name="torso_t0" type="fixed">
		<parent link="base"/>
		<child link="torso"/>
		<dynamics damping="1.0" friction="0.0001"/>
		<origin rpy="0.00000 -0.00000 0.00000" xyz="0.00000 0.00000 0.00000"/>
		<axis xyz="0.00000 0.00000 0.00000"/>
	</joint>
	<joint name="joint_dummy1" type="fixed">
		<parent link="right_l6"/>
		<child link="1in rectangular block_C.SLDPRT"/>
		<dynamics damping="1.0" friction="0.0001"/>
		<origin rpy="0.00000 0.00000 0.00000" xyz="0.00000 0.00000 0.00000"/>
		<axis xyz="0.00000 0.00000 1.00000"/>
	</joint>
</robot>
